<?xml version="1.0" ?>
<mujoco model="furniture_assembly">
  <compiler angle="radian" inertiafromgeom="auto" meshdir="/Users/larsankile/code/furniture-bench/furniture_bench/assets/franka_description_ros/franka_description/meshes" />

  <option timestep="0.0005" gravity="0 0 -9.81" iterations="200" solver="Newton" tolerance="1e-12" viscosity="10.0">
    <flag contact="enable" energy="enable" />
  </option>

  <size njmax="500" nconmax="200" />

  <default>
    <geom condim="4" friction="5.0 1.0 1.0"
          solimp="0.999 0.999 0.0001 0.5 2" solref="0.002 1"
          margin="0.0" gap="0" />
  </default>

  <visual>
    <headlight ambient="0.3 0.3 0.3" diffuse="0.6 0.6 0.6" specular="0.1 0.1 0.1" />
  </visual>

  <asset>
    <!-- Ground texture -->
    <texture name="grid" type="2d" builtin="checker" width="512" height="512"
             rgb1="0.2 0.2 0.2" rgb2="0.3 0.3 0.3" />
    <material name="grid" texture="grid" texrepeat="10 10" reflectance="0.1" />

    <!-- Table texture - natural wood tone -->
    <texture name="wood" type="2d" builtin="checker" width="512" height="512"
             rgb1="0.6 0.45 0.3" rgb2="0.55 0.4 0.25" />
    <material name="table_mat" texture="wood" texrepeat="8 8" specular="0.2" shininess="0.3" />

    <!-- Furniture meshes -->
    <mesh name="square_table_top_mesh"
          file="/Users/larsankile/code/furniture-bench/furniture_bench/assets/furniture/mesh/square_table/square_table_top_fixed.obj" />
    <mesh name="square_table_leg_mesh"
          file="/Users/larsankile/code/furniture-bench/furniture_bench/assets/furniture/mesh/square_table/square_table_leg.obj" />
  </asset>

  <worldbody>
    <!-- Lighting - softer and more diffuse -->
    <light pos="0 0 3" dir="0 0 -1" directional="false" castshadow="true"
           diffuse="0.5 0.5 0.5" specular="0.2 0.2 0.2" />
    <light pos="1 1 3" dir="-0.3 -0.3 -1" directional="false"
           diffuse="0.4 0.4 0.4" specular="0.1 0.1 0.1" />
    <light pos="-1 -1 2.5" dir="0.3 0.3 -1" directional="false"
           diffuse="0.3 0.3 0.3" specular="0.1 0.1 0.1" />

    <!-- Ground plane -->
    <geom name="ground" type="plane" size="2 2 0.1" material="grid" />

    <!-- Simple robot arm placeholder (7 DOF) -->
    <body name="robot_base" pos="-0.4 0 0.42">
      <geom type="cylinder" size="0.06 0.03" rgba="0.3 0.3 0.3 1"/>
      <body name="link1" pos="0 0 0.05">
        <joint name="joint1" type="hinge" axis="0 0 1" range="-2.8 2.8"/>
        <geom type="cylinder" size="0.05 0.1" rgba="0.8 0.8 0.8 1"/>
        <body name="link2" pos="0 0 0.15">
          <joint name="joint2" type="hinge" axis="0 1 0" range="-1.76 1.76"/>
          <geom type="cylinder" size="0.045 0.12" rgba="0.8 0.8 0.8 1"/>
          <body name="link3" pos="0 0 0.15">
            <joint name="joint3" type="hinge" axis="0 0 1" range="-2.8 2.8"/>
            <geom type="cylinder" size="0.04 0.1" rgba="0.8 0.8 0.8 1"/>
            <body name="link4" pos="0 0 0.13">
              <joint name="joint4" type="hinge" axis="0 -1 0" range="-3 -0.07"/>
              <geom type="cylinder" size="0.04 0.1" rgba="0.8 0.8 0.8 1"/>
              <body name="link5" pos="0 0 0.12">
                <joint name="joint5" type="hinge" axis="0 0 1" range="-2.8 2.8"/>
                <geom type="cylinder" size="0.035 0.08" rgba="0.8 0.8 0.8 1"/>
                <body name="link6" pos="0 0 0.1">
                  <joint name="joint6" type="hinge" axis="0 1 0" range="-0.02 3.75"/>
                  <geom type="cylinder" size="0.03 0.06" rgba="0.8 0.8 0.8 1"/>
                  <body name="ee" pos="0 0 0.08">
                    <joint name="joint7" type="hinge" axis="0 0 1" range="-2.8 2.8"/>
                    <geom type="box" size="0.04 0.02 0.02" rgba="0.2 0.6 0.2 1"/>
                  </body>
                </body>
              </body>
            </body>
          </body>
        </body>
      </body>
    </body>

    <!-- Work table - fixed (welded to world) -->
    <body name="work_table" pos="0 0 0.4">
      <geom name="table_top" type="box" size="0.6 0.8 0.02"
            material="table_mat" mass="10" />
      <geom name="table_leg1" type="box" size="0.03 0.03 0.4"
            pos="0.55 0.75 -0.4" rgba="0.6 0.6 0.6 1" />
      <geom name="table_leg2" type="box" size="0.03 0.03 0.4"
            pos="0.55 -0.75 -0.4" rgba="0.6 0.6 0.6 1" />
      <geom name="table_leg3" type="box" size="0.03 0.03 0.4"
            pos="-0.55 0.75 -0.4" rgba="0.6 0.6 0.6 1" />
      <geom name="table_leg4" type="box" size="0.03 0.03 0.4"
            pos="-0.55 -0.75 -0.4" rgba="0.6 0.6 0.6 1" />
    </body>

    <!-- Furniture parts (free-floating) -->
    <!-- Square table top -->
    <body name="square_table_top" pos="0.2 0 0.52" quat="0.7071 0.7071 0 0">
      <freejoint />
      <geom type="mesh" mesh="square_table_top_mesh"
            rgba="0.8 0.6 0.4 1" density="498.68" />
    </body>

    <!-- Square table leg 1 -->
    <body name="square_table_leg1" pos="0.35 0.15 0.45">
      <freejoint />
      <geom type="mesh" mesh="square_table_leg_mesh"
            rgba="0.8 0.6 0.4 1" density="369.98" />
    </body>
  </worldbody>
</mujoco>
